<?xml version="1.0" encoding="UTF-8"?>
<!-- Generated by org.testng.reporters.JUnitReportReporter -->
<testsuite hostname="5CD6102FYR" name="com.letv.ark.test.AutoTest" tests="2" failures="0" timestamp="17 May 2017 06:40:26 GMT" time="0.126" errors="2">
  <testcase name="test" time="0.009" classname="com.letv.ark.test.AutoTest">
    <error type="java.lang.AssertionError" message="测试用例:Login.xml运行报错,报错信息为：=:null">
      <![CDATA[java.lang.AssertionError: 测试用例:Login.xml运行报错,报错信息为：=:null
	at org.testng.Assert.fail(Assert.java:89)
	at com.letv.ark.test.AutoTest.test(Unknown Source)
	at sun.reflect.NativeMethodAccessorImpl.invoke0(Native Method)
	at sun.reflect.NativeMethodAccessorImpl.invoke(Unknown Source)
	at sun.reflect.DelegatingMethodAccessorImpl.invoke(Unknown Source)
	at java.lang.reflect.Method.invoke(Unknown Source)
	at org.testng.internal.MethodInvocationHelper.invokeMethod(MethodInvocationHelper.java:80)
	at org.testng.internal.Invoker.invokeMethod(Invoker.java:702)
	at org.testng.internal.Invoker.invokeTestMethod(Invoker.java:894)
	at org.testng.internal.Invoker.invokeTestMethods(Invoker.java:1219)
	at org.testng.internal.TestMethodWorker.invokeTestMethods(TestMethodWorker.java:127)
	at org.testng.internal.TestMethodWorker.run(TestMethodWorker.java:111)
	at org.testng.TestRunner.privateRun(TestRunner.java:768)
	at org.testng.TestRunner.run(TestRunner.java:617)
	at org.testng.SuiteRunner.runTest(SuiteRunner.java:334)
	at org.testng.SuiteRunner.runSequentially(SuiteRunner.java:329)
	at org.testng.SuiteRunner.privateRun(SuiteRunner.java:291)
	at org.testng.SuiteRunner.run(SuiteRunner.java:240)
	at org.testng.SuiteRunnerWorker.runSuite(SuiteRunnerWorker.java:53)
	at org.testng.SuiteRunnerWorker.run(SuiteRunnerWorker.java:87)
	at org.testng.TestNG.runSuitesSequentially(TestNG.java:1188)
	at org.testng.TestNG.runSuitesLocally(TestNG.java:1113)
	at org.testng.TestNG.run(TestNG.java:1025)
	at org.testng.TestNG.privateMain(TestNG.java:1328)
	at org.testng.TestNG.main(TestNG.java:1297)
]]>
    </error>
  </testcase> <!-- test -->
  <testcase name="test" time="0.117" classname="com.letv.ark.test.AutoTest">
    <error type="java.lang.AssertionError" message="测试用例:Media_Add.xml运行报错,报错信息为：=:null">
      <![CDATA[java.lang.AssertionError: 测试用例:Media_Add.xml运行报错,报错信息为：=:null
	at org.testng.Assert.fail(Assert.java:89)
	at com.letv.ark.test.AutoTest.test(Unknown Source)
	at sun.reflect.NativeMethodAccessorImpl.invoke0(Native Method)
	at sun.reflect.NativeMethodAccessorImpl.invoke(Unknown Source)
	at sun.reflect.DelegatingMethodAccessorImpl.invoke(Unknown Source)
	at java.lang.reflect.Method.invoke(Unknown Source)
	at org.testng.internal.MethodInvocationHelper.invokeMethod(MethodInvocationHelper.java:80)
	at org.testng.internal.Invoker.invokeMethod(Invoker.java:702)
	at org.testng.internal.Invoker.invokeTestMethod(Invoker.java:894)
	at org.testng.internal.Invoker.invokeTestMethods(Invoker.java:1219)
	at org.testng.internal.TestMethodWorker.invokeTestMethods(TestMethodWorker.java:127)
	at org.testng.internal.TestMethodWorker.run(TestMethodWorker.java:111)
	at org.testng.TestRunner.privateRun(TestRunner.java:768)
	at org.testng.TestRunner.run(TestRunner.java:617)
	at org.testng.SuiteRunner.runTest(SuiteRunner.java:334)
	at org.testng.SuiteRunner.runSequentially(SuiteRunner.java:329)
	at org.testng.SuiteRunner.privateRun(SuiteRunner.java:291)
	at org.testng.SuiteRunner.run(SuiteRunner.java:240)
	at org.testng.SuiteRunnerWorker.runSuite(SuiteRunnerWorker.java:53)
	at org.testng.SuiteRunnerWorker.run(SuiteRunnerWorker.java:87)
	at org.testng.TestNG.runSuitesSequentially(TestNG.java:1188)
	at org.testng.TestNG.runSuitesLocally(TestNG.java:1113)
	at org.testng.TestNG.run(TestNG.java:1025)
	at org.testng.TestNG.privateMain(TestNG.java:1328)
	at org.testng.TestNG.main(TestNG.java:1297)
]]>
    </error>
  </testcase> <!-- test -->
</testsuite> <!-- com.letv.ark.test.AutoTest -->
